<mujoco model="soccerbot">
  <compiler angle="radian" autolimits="true"/>
  <size/>

  <default>
    <motor ctrlrange="-4 4" ctrllimited="true"/>
    <default class="body">
      <geom type="capsule" condim="1" friction="1.0 0.05 0.05" solimp=".9 .99 .003" solref=".015 1"/>
      <joint type="hinge" damping="0.1" stiffness="5" armature=".007" limited="true" solimplimit="0 .99 .01"/>
      <site size=".04" group="3"/>
      <default class="force-torque">
        <site type="box" size=".01 .01 .02" rgba="1 0 0 1" />
      </default>
      <default class="touch">
        <site type="capsule" rgba="0 0 1 .3"/>
      </default>
    </default>
  </default>


  <worldbody>
    <geom name="floor" type="plane" conaffinity="1" size="100 100 .2" material="grid"/>
    <body name="pelvis" pos="0 0 1" childclass="body">
      <freejoint name="root"/>
      <site name="root" class="force-torque"/>
      <geom name="pelvis" type="sphere" pos="0 0.0725 -0.15" size=".0001" density="0"/>
      <site name="pelvis" class="touch" type="sphere" pos="0 0.0725 -0.15" size="0.00011"/>

      <body name="/torso" pos="-0.0425 0.0725 0.11">
        <inertial pos="0.0082498 -0.0017440 -0.0522479" quat="0.99973 0.0232243 0 0" mass="1.529" diaginertia="4.323e-3 5.198e-3 3.567e-3"/>
        <geom name="/torso" size="0.065 0.0725 0.076" pos="0 0 -0.052" type="box"/>
        <site name="/torso" class="touch" type="box" pos="0 0 -0.052" size="0.065 0.0725 0.076"/>

        <body name="/neck" pos="0 0 0.05875">
        <inertial pos="0 -0.0006476 0.0092453" quat="0.707107 0.707107 0 0" mass="0.011294" diaginertia="5.489e-06 4.955e-06 1.433e-06"/>
        <joint name="head_motor_0" pos="0 0 0" axis="0 0 1" range="-1.5708 1.5708" damping="0.01" frictionloss="0.1"/>
        <geom name="/neck" size="0.011 0.02615 0.0165" pos="0 0 0.0165" type="box"/>
        <site name="/neck" size="0.011 0.02615 0.0165" pos="0 0 0.0165" type="box"/>
        <site name="neck" class="force-torque"/>

          <body name="/head" pos="0 0 0.024">
            <inertial pos="0.0234181 0.00179728 0.0263433" quat="0.958743 0.0130939 0.283717 -0.0120458" mass="0.292" diaginertia="0.000246571 0.000211105 0.000124979"/>
            <joint name="head_motor_1" pos="0 0 0" axis="0 1 0" range="-2.35619 2.35619" damping="0.01" frictionloss="0.1"/>
            <geom name="/head" size="0.0356 0.047 0.03895" pos="-0.013 0 0.025" type="box"/>
            <site name="/head" size="0.0356 0.047 0.03895" pos="-0.013 0 0.025" type="box"/>
            <site name="head" class="force-torque"/>

          </body>
      </body>

        <body name="/left_bicep" pos="-0.0157 0.0725 0.0175">
          <site name="left_bicep" class="force-torque"/>
          <inertial pos="0 0.02579 -0.04955" quat="0.99973 0.0232243 0 0" mass="0.000213" diaginertia="0.0002824 0.000274942 2.37884e-05"/>
          <joint name="left_arm_motor_0" pos="0 0 0" axis="0 -1 0" range="-1.5708 3.92699" damping="0.01" frictionloss="0.1"/>
          <geom name="/left_bicep" size="0.02 0.02388 0.0615" pos="0 0.0245 -0.05001" type="box"/>
          <site name="/left_bicep" class="touch" size="0.02 0.02388 0.0615" pos="0 0.0245 -0.05001" type="box"/>

          <body name="/left_forearm" pos="0 0 -0.1">
            <site name="left_forearm" class="force-torque"/>
            <inertial pos="0 0.0245 -0.0546097" quat="0.999988 0 -0.00494983 0" ma diaginertia="0.00011301 0.000107 1.19901e-05"/>
            <joint name="left_arm_motor_1" pos="0 0 0" axis="0 -1 0" range="0 3.14159" damping="0.01" frictionloss="0.1"/>
            <geom name="/left_forearm" size="0.0175 0.0245 0.072" pos="-0.0055 0.0255 -0.06" type="box"/>
            <site name="/left_forearm" size="0.0175 0.0245 0.072" pos="-0.0055 0.0255 -0.06" type="box"/>

            <body name="/left_hand" pos="0 0 -0.03">
                <geom name="/left_hand" type="sphere" size=".0004" density="0"/>
                <site name="/left_hand" class="touch" type="sphere" size=".0004"/>
            </body>
          </body>


        </body>

        <body name="/right_bicep" pos="-0.0157 -0.0725 0.0175">
          <site name="right_bicep" class="force-torque"/>
          <inertial pos="0 -0.02579 -0.04955" quat="0.99973 -0.0232243 0 0" mass="0.000213" diaginertia="0.0002824 0.000274942 2.37884e-05"/>
          <joint name="right_arm_motor_0" pos="0 0 0" axis="0 -1 0" range="-1.5708 3.92699" damping="0.01" frictionloss="0.1"/>
          <geom name="/right_bicep" size="0.02 0.02388 0.0615" pos="0 -0.0255 -0.05001" type="box"/>
          <site name="/right_bicep" size="0.02 0.02388 0.0615" pos="0 -0.0255 -0.05001" type="box"/>

          <body name="/right_forearm" pos="0 0 -0.1">
            <site name="right_forearm" class="force-torque"/>
            <inertial pos="0 -0.0245 -0.0546097" quat="0.999988 0 0.00494983 0" mass="0.0457" diaginertia="0.00011301 0.000107 1.19901e-05"/>
            <joint name="right_arm_motor_1" pos="0 0 0" axis="0 -1 0" range="0 3.14159" damping="0.01" frictionloss="0.1"/>
            <geom name="/right_forearm" size="0.0175 0.0245 0.072" pos="-0.0055 -0.0255 -0.06" type="box"/>
            <site name="/right_forearm" size="0.0175 0.0245 0.072" pos="-0.0055 -0.0255 -0.06" type="box"/>

            <body name="/right_hand" pos="0 0 -0.03">
                <geom name="/right_hand" type="sphere" size=".0004" density="0"/>
                <site name="/right_hand" class="touch" type="sphere" size=".00041"/>
            </body>
          </body>
        </body>

     </body>

      <body name="/left_hip_side" pos="-0.04 0.11 -0.0575">
        <inertial pos="0.0003695 0 0.01689" quat="0.5 0.5 0.5 0.5" mass="0.009364" diaginertia="5e-06 4e-06 2e-06"/>
        <joint name="left_leg_motor_0" pos="0 0 0" axis="0 0 -1" range="-1.309 0.524" damping="0.01" frictionloss="0.1"/>
        <joint name="left_leg_motor_1" pos="0 0 0" axis="1 0 0" range="-0.785398 1.5708" damping="0.01" frictionloss="0.1"/>
        <joint name="left_leg_motor_2" pos="0 0 0" axis="0 -1 0" range="-0.785398 2.35619" damping="0.01" frictionloss="0.1"/>
        <geom name="/left_hip_side" size="0.02425 0.011 2.5e-05" pos="0 0 0.03" type="box"/>
        <site name="/left_hip_side" size="0.02425 0.011 2.5e-05" pos="0 0 0.03" type="box"/>
        <site name="left_hip_side" class="force-torque"/>

        <body name="/left_hip_front" pos="0 0 0">
          <inertial pos="-0.02093 0 -0.011313" quat="0.507623 0.492259 0.492259 0.507623" mass="0.153186" diaginertia="0.000118 0.000106061 4.09385e-05"/>

          <geom name="/left_hip_front" size="0.0418735 0.024425 0.0253" pos="-0.02187 0 -0.01332" type="box"/>
          <site name="/left_hip_front" size="0.0418735 0.024425 0.0253" pos="-0.02187 0 -0.01332" type="box"/>
          <site name="left_hip_front" class="force-torque"/>

          <body name="/left_thigh" pos="0 0 0">
            <inertial pos="0.0019422 0.0001419 -0.0469409" quat="0.994539 0 0 0.104366" mass="0.021438" diaginertia="2.54244e-05 1.55756e-05 1e-05"/>
            <geom name="/left_thigh" size="0.011 0.024 0.0555" pos="0 0 -0.0445" type="box"/>
            <site name="/left_thigh" size="0.011 0.024 0.0555" pos="0 0 -0.0445" type="box"/>
            <site name="left_thigh" class="force-torque"/>

            <body name="/left_calve" pos="0 0 -0.089">
              <inertial pos="0 -3.259e-07 -1.50123e-05" quat="0.999829 -0.0184837 0 0" mass="0.086547" diaginertia="5.4e-05 4.6037e-05 1.8963e-05"/>
              <joint name="left_leg_motor_3" pos="0 0 0" axis="0 -1 0" range="-2.793 0" damping="0.01" frictionloss="0.1"/>
              <geom name="/left_calve" size="0.0159415 0.024 0.0528415" pos="0 0 -0.03385" type="box"/>
              <site name="/left_calve" size="0.0159415 0.024 0.0528415" pos="0 0 -0.03385" type="box"/>
              <site name="left_calve" class="force-torque"/>

              <body name="/left_ankle" pos="0 0 -0.0865">
                <inertial pos="-2.0939e-05 0 1.1313e-05" quat="0.492259 0.507623 0.507623 0.492259" mass="0.153186" diaginertia="0.000118 0.000106061 4.09385e-05"/>
                <joint name="left_leg_motor_4" pos="0 0 0" axis="0 -1 0" range="-0.785398 1.5708" damping="0.01" frictionloss="0.1"/>
                <joint name="left_leg_motor_5" pos="0 0 0" axis="1 0 0" range="-0.785398 0.785398" damping="0.01" frictionloss="0.1"/>
                <geom name="/left_ankle" size="0.0453845 0.021 0.0253" pos="-0.02014 0 0.01031" type="box"/>
                <site name="/left_ankle" size="0.0453845 0.021 0.0253" pos="-0.02014 0 0.01031" type="box"/>
                <site name="left_ankle" class="force-torque"/>

                <body name="/left_foot" pos="0 0 0">
                  <inertial pos="-0.020939 0 0.011313" quat="0 0.707107 0 0.707107" mass="0.023216" diaginertia="2.2e-05 1.8e-05 6e-06"/>

                  <geom name="/left_foot" size="0.045 0.025 0.0015" pos="0.00225 0.00401 -0.0205" type="box"/>
                  <site name="/left_foot" size="0.045 0.025 0.0015" pos="0.00225 0.00401 -0.0205" type="box"/>
                  <site name="left_foot" class="force-torque"/>

                </body>
              </body>
            </body>
          </body>
        </body>
      </body>

      <body name="/right_hip_side" pos="-0.04 0.0375 -0.0575">
        <inertial pos="0.0003695 0 0.01689" quat="0.5 0.5 0.5 0.5" mass="0.009364" diaginertia="5e-06 4e-06 2e-06"/>
        <joint name="right_leg_motor_0" pos="0 0 0" axis="0 0 1" range="-1.309 0.524" damping="0.01" frictionloss="0.1"/>
        <joint name="right_leg_motor_1" pos="0 0 0" axis="-1 0 0" range="-0.785398 1.5708" damping="0.01" frictionloss="0.1"/>
        <joint name="right_leg_motor_2" pos="0 0 0" axis="0 -1 0" range="-0.785398 2.35619" damping="0.01" frictionloss="0.1"/>
        <geom name="/right_hip_side" size="0.02425 0.011 2.5e-05" pos="0 0 0.03" type="box"/>
        <site name="/right_hip_side" size="0.02425 0.011 2.5e-05" pos="0 0 0.03" type="box"/>
        <site name="right_hip_side" class="force-torque"/>

        <body name="/right_hip_front" pos="0 0 0">
          <inertial pos="-0.02093 0 -0.011313" quat="0.507623 0.492259 0.492259 0.507623" mass="0.153186" diaginertia="0.000118 0.000106061 4.09385e-05"/>

          <geom name="/right_hip_front" size="0.0418735 0.024425 0.0253" pos="-0.02187 0 -0.01332" type="box"/>
          <site name="/right_hip_front" size="0.0418735 0.024425 0.0253" pos="-0.02187 0 -0.01332" type="box"/>
          <site name="right_hip_front" class="force-torque"/>

          <body name="/right_thigh" pos="0 0 0">
            <inertial pos="0.0019422 -0.0001419 -0.0469409" quat="0.994539 0 0 -0.104366" mass="0.021438" diaginertia="2.54244e-05 1.55756e-05 1e-05"/>

            <geom name="/right_thigh" size="0.011 0.024 0.0555" pos="0 0 -0.0445" type="box"/>
            <site name="/right_thigh" size="0.011 0.024 0.0555" pos="0 0 -0.0445" type="box"/>
            <site name="right_thigh" class="force-torque"/>

            <body name="/right_calve" pos="0 0 -0.089">
              <inertial pos="0 3.259e-07 -1.50123e-05" quat="0.999829 -0.0184837 0 0" mass="0.086547" diaginertia="5.4e-05 4.6037e-05 1.8963e-05"/>
              <joint name="right_leg_motor_3" pos="0 0 0" axis="0 -1 0" range="-2.793 0" damping="0.01" frictionloss="0.1"/>
              <geom name="/right_calve" size="0.0159415 0.024 0.0528415" pos="0 0 -0.03385" type="box"/>
              <site name="/right_calve" size="0.0159415 0.024 0.0528415" pos="0 0 -0.03385" type="box"/>
              <site name="right_calve" class="force-torque"/>

              <body name="/right_ankle" pos="0 0 -0.0865">
                <inertial pos="-2.0939e-05 0 1.1313e-05" quat="0.492259 0.507623 0.507623 0.492259" mass="0.153186" diaginertia="0.000118 0.000106061 4.09385e-05"/>
                <joint name="right_leg_motor_4" pos="0 0 0" axis="0 -1 0" range="-0.785398 1.5708" damping="0.01" frictionloss="0.1"/>
                <joint name="right_leg_motor_5" pos="0 0 0" axis="-1 0 0" range="-0.785398 0.785398" damping="0.01" frictionloss="0.1"/>
                <geom name="/right_ankle" size="0.0453845 0.021 0.0253" pos="-0.02014 0 0.01031" type="box"/>
                <site name="/right_ankle" size="0.0453845 0.021 0.0253" pos="-0.02014 0 0.01031" type="box"/>
                <site name="right_ankle" class="force-torque"/>

                <body name="/right_foot" pos="0 0 0">
                  <inertial pos="-0.020939 0 0.011313" quat="0 0.707107 0 0.707107" mass="0.023216" diaginertia="2.2e-05 1.8e-05 6e-06"/>

                  <geom name="/right_foot" size="0.045 0.025 0.0015" pos="0.00225 -0.00401 -0.0205" type="box"/>
                  <site name="/right_foot" size="0.045 0.025 0.0015" pos="0.00225 -0.00401 -0.0205" type="box"/>
                  <site name="right_foot" class="force-torque"/>

                </body>
              </body>
            </body>
          </body>
        </body>
      </body>
    </body>
  </worldbody>

  <actuator>
    <motor name='head_motor_0'       gear='100' joint='head_motor_0'/>
    <motor name='head_motor_1'       gear='100' joint='head_motor_1'/>
    <motor name='left_arm_motor_0'  gear='100' joint='left_arm_motor_0'/>
    <motor name='left_arm_motor_1'  gear='100' joint='left_arm_motor_1'/>
    <motor name='right_arm_motor_0'  gear='100' joint='right_arm_motor_0'/>
    <motor name='right_arm_motor_1'  gear='100' joint='right_arm_motor_1'/>
    <motor name='left_leg_motor_0'  gear='100' joint='left_leg_motor_0'/>
    <motor name='left_leg_motor_1'  gear='100' joint='left_leg_motor_1'/>
    <motor name='left_leg_motor_2'  gear='100' joint='left_leg_motor_2'/>
    <motor name='left_leg_motor_3'  gear='100' joint='left_leg_motor_3'/>
    <motor name='left_leg_motor_4'  gear='100' joint='left_leg_motor_4'/>
    <motor name='left_leg_motor_5'  gear='100' joint='left_leg_motor_5'/>
    <motor name='right_leg_motor_0'  gear='100' joint='right_leg_motor_0'/>
    <motor name='right_leg_motor_1'  gear='100' joint='right_leg_motor_1'/>
    <motor name='right_leg_motor_2'  gear='100' joint='right_leg_motor_2'/>
    <motor name='right_leg_motor_3'  gear='100' joint='right_leg_motor_3'/>
    <motor name='right_leg_motor_4'  gear='100' joint='right_leg_motor_4'/>
    <motor name='right_leg_motor_5'  gear='100' joint='right_leg_motor_5'/>

  </actuator>

  <sensor>
    <subtreelinvel name="pelvis_subtreelinvel" body="pelvis"/>
    <accelerometer name="root_accel"    site="root"/>
    <velocimeter name="root_vel"        site="root"/>
    <gyro name="root_gyro"              site="root"/>

    <force name="head_force"       site="head"/>
    <force name="neck_force"       site="neck"/>
    <force name="left_bicep_force"       site="left_bicep"/>
    <force name="left_forearm_force"       site="left_forearm"/>
    <force name="right_bicep_force"       site="right_bicep"/>
    <force name="right_forearm_force"       site="right_forearm"/>
    <force name="left_hip_side_force"       site="left_hip_side"/>
    <force name="left_hip_front_force"       site="left_hip_front"/>
    <force name="left_thigh_force"       site="left_thigh"/>
    <force name="left_calve_force"       site="left_calve"/>
    <force name="left_ankle_force"       site="left_ankle"/>
    <force name="left_foot_force"       site="left_foot"/>
    <force name="right_hip_side_force"       site="right_hip_side"/>
    <force name="right_hip_front_force"       site="right_hip_front"/>
    <force name="right_thigh_force"       site="right_thigh"/>
    <force name="right_calve_force"       site="right_calve"/>
    <force name="right_ankle_force"       site="right_ankle"/>
    <force name="right_foot_force"       site="right_foot"/>


    <torque name="head_torque"     site="head"/>
    <torque name="neck_torque"       site="neck"/>
    <torque name="left_bicep_torque"       site="left_bicep"/>
    <torque name="left_forearm_torque"       site="left_forearm"/>
    <torque name="right_bicep_torque"       site="right_bicep"/>
    <torque name="right_forearm_torque"       site="right_forearm"/>
    <torque name="left_hip_side_torque"       site="left_hip_side"/>
    <torque name="left_hip_front_torque"       site="left_hip_front"/>
    <torque name="left_thigh_torque"       site="left_thigh"/>
    <torque name="left_calve_torque"       site="left_calve"/>
    <torque name="left_ankle_torque"       site="left_ankle"/>
    <torque name="left_foot_torque"       site="left_foot"/>
    <torque name="right_hip_side_torque"       site="right_hip_side"/>
    <torque name="right_hip_front_torque"       site="right_hip_front"/>
    <torque name="right_thigh_torque"       site="right_thigh"/>
    <torque name="right_calve_torque"       site="right_calve"/>
    <torque name="right_ankle_torque"       site="right_ankle"/>
    <torque name="right_foot_torque"       site="right_foot"/>

    <touch name="head_touch"           site="/head"/>
    <touch name="neck_touch"           site="/neck"/>
    <touch name="left_bicep_touch"       site="/left_bicep"/>
    <touch name="left_forearm_touch"       site="/left_forearm"/>
    <touch name="right_bicep_touch"       site="/right_bicep"/>
    <touch name="right_forearm_touch"       site="/right_forearm"/>
    <touch name="left_hip_side_touch"       site="/left_hip_side"/>
    <touch name="left_hip_front_touch"       site="/left_hip_front"/>
    <touch name="left_thigh_touch"       site="/left_thigh"/>
    <touch name="left_calve_touch"       site="/left_calve"/>
    <touch name="left_ankle_touch"       site="/left_ankle"/>
    <touch name="left_foot_touch"       site="/left_foot"/>
    <touch name="right_hip_side_touch"       site="/right_hip_side"/>
    <touch name="right_hip_front_touch"       site="/right_hip_front"/>
    <touch name="right_thigh_touch"       site="/right_thigh"/>
    <touch name="right_calve_touch"       site="/right_calve"/>
    <touch name="right_ankle_touch"       site="/right_ankle"/>
    <touch name="right_foot_touch"       site="/right_foot"/>
  </sensor>

</mujoco>
